<?xml version="1.0"?>

<robot xmlns:xacro="http://www.ros.org/wiki/xacro" name = "barista_robot">

<!-- Include wheel xacro -->
<xacro:include filename="$(find barista_robot_description)/xacro/wheel.xacro"/>
<!-- Include wheel standoff rods -->
<xacro:include filename="$(find barista_robot_description)/xacro/standoff.xacro"/>
<!-- Include wheel cup holder tray -->
<xacro:include filename="$(find barista_robot_description)/xacro/cup_holder_tray.xacro"/>
<!-- Include laser scan -->
<xacro:include filename="$(find barista_robot_description)/xacro/laser_scan.xacro"/>

<!-- Argumnets -->
<xacro:arg name="include_laser" default="true"/>
<xacro:property name="include_laser" value="$(arg include_laser)" />

<xacro:arg name="robot_name" default="barista"/>
<xacro:property name="robot_name" value="$(arg robot_name)" />


<!-- Colors -->
<material name="red">
      <color rgba="1.0 0.0 0.0 1"/>
</material>

<material name="green">
    <color rgba="0.0 1.0 0.0 1"/>
</material>

<material name="white">
    <color rgba="1.0 1.0 1.0 1"/>
</material>

<material name="blue">
    <color rgba="0.0 0.0 1.0 1"/>
</material>


    <link name="base_link">
        <origin xyz="0 0 0" rpy="0 0 0"/>
    </link>

    <!-- Robot body -->
    <link name = "chassis">

        <visual>
            <origin xyz="0 0 0" rpy="0 0 0"/>
            <geometry>
                <cylinder length ="0.155" radius="0.178"/>
            </geometry>
            <material name="red"/>
        </visual>

        <collision> 
            <origin xyz="0 0 0" rpy="0 0 0"/>
            <geometry>
                <cylinder length ="0.155" radius="0.178"/>
            </geometry>
        </collision>

        <inertial>
            <mass value="10"/>
            <origin xyz="0 0 0" rpy="0 0 0"/>
            <inertia ixx="0.099" ixy="0" ixz="0" iyy="0.099" iyz="0" izz="0.158"/>
        </inertial>

    </link>

    <gazebo reference="chassis">
        <material>Gazebo/Red</material>
    </gazebo>


    <!-- Joint base_link to chassis -->
    <joint name = "base_link_joint" type ="fixed">
        <origin xyz="0 0 0" rpy="0 0 0"/>
        <parent link = "base_link" />
        <child link = "chassis" />
    </joint>

    <!-- Wheel left -->
    <xacro:wheel wheel_name="left_wheel"/>

    <joint name="left_wheel_joint" type="continuous">
        <origin xyz="0 0.15 -0.0775" rpy="0 0 0"/>
        <parent link="chassis"/>
        <child link="left_wheel"/>
        <axis xyz="0 1 0" rpy="0 0 0"/>
        <limit effort="1000" velocity="1000"/>
        <joint_properties damping="1.0" friction="1.0"/>
    </joint>

    <!-- Wheel right -->
    <xacro:wheel wheel_name="right_wheel"/>

    <joint name="right_wheel_joint" type="continuous">
        <origin xyz="0 -0.15 -0.0775" rpy="0 0 0"/>
        <parent link="chassis"/>
        <child link="right_wheel"/>
        <axis xyz="0 1 0" rpy="0 0 0"/>
        <limit effort="1000" velocity="1000"/>
        <joint_properties damping="1.0" friction="1.0"/>
    </joint>


    <!-- Front caster wheel -->

    <link name="front_yaw_link">

      <visual>
        <origin rpy="0 1.5707 1.5707" xyz="0 0 0"/>
        <geometry>          
          <cylinder length="0.001" radius="0.005"/>
        </geometry>
        <material name="blue"/>
      </visual>

      <collision>
        <origin rpy="0 1.5707 1.5707" xyz="0 0 0"/>
        <geometry>          
          <cylinder length="0.001" radius="0.005"/>
        </geometry>
      </collision>

      <inertial>
        <mass value="0.5"/>
        <origin xyz="0 0 0" rpy="0 0 0"/>
        <inertia ixx="0.000245" ixy="0" ixz="0" iyy="0.000245" iyz="0" izz="0.000245"/>
    </inertial>

    </link>

  <joint name="front_yaw_joint" type="continuous">
    <origin xyz="0.14 0.0 -0.0775" rpy="0 0 0"/>
    <parent link="chassis" />
    <child link="front_yaw_link" />
    <axis xyz="0 0 1" />
    <limit effort="1000.0" velocity="100.0" />
    <dynamics damping="0.05" friction="0.1"/>
  </joint>



  <link name="front_roll_link">
      <visual>
        <origin rpy="0 1.5707 1.5707" xyz="0 0 0"/>
        <geometry>
          <cylinder length="0.001" radius="0.005"/>
        </geometry>
        <material name="red"/>
      </visual>

      <collision>
        <origin rpy="0 1.5707 1.5707" xyz="0 0 0"/>
        <geometry>
          <cylinder length="0.001" radius="0.005"/>
        </geometry>
      </collision>

      <inertial>
        <mass value="0.5"/>
        <origin xyz="0 0 0" rpy="0 0 0"/>
        <inertia ixx="0.000245" ixy="0" ixz="0" iyy="0.000245" iyz="0" izz="0.000245"/>
    </inertial>

  </link>

  <joint name="front_roll_joint" type="continuous">
    <origin rpy="0 0 0" xyz="0 0 0" />
    <parent link="front_yaw_link" />
    <child link="front_roll_link" />
    <axis xyz="1 0 0" />
    <limit effort="1000.0" velocity="100.0" />
    <dynamics damping="0.0" friction="0.1"/>
  </joint>


  <link name="front_pitch_link">
    <visual>
      <origin rpy="0 1.5707 1.5707" xyz="0 0 0"/>
      <geometry>
        <sphere radius="0.035"/>
      </geometry>
      <material name="green"/>
    </visual>

    <collision>
      <origin rpy="0 1.5707 1.5707" xyz="0 0 0"/>
      <geometry>
        <sphere radius="0.035"/>
      </geometry>
    </collision>

    <inertial>
        <mass value="0.5"/>
        <origin xyz="0 0 0" rpy="0 0 0"/>
        <inertia ixx="0.000245" ixy="0" ixz="0" iyy="0.000245" iyz="0" izz="0.000245"/>
    </inertial>

  </link>

  <gazebo reference="front_pitch_link">
        <material>Gazebo/Green</material>
        <mu1>0.1</mu1>
        <mu2>0.1</mu2>
    </gazebo>



  <joint name="front_pitch_joint" type="continuous">
    <origin rpy="0 0 0" xyz="0 0 0" />
    <parent link="front_roll_link" />
    <child link="front_pitch_link" />
    <axis xyz="0 1 0" />
    <limit effort="1000.0" velocity="100.0" />
    <dynamics damping="0.0" friction="0.1"/>
  </joint>


    <!-- Back caster wheel -->
    <link name="back_yaw_link">

      <visual>
        <origin rpy="0 1.5707 1.5707" xyz="0 0 0"/>
        <geometry>          
          <cylinder length="0.001" radius="0.005"/>
        </geometry>
        <material name="blue"/>
      </visual>

      <collision>
        <origin rpy="0 1.5707 1.5707" xyz="0 0 0"/>
        <geometry>          
          <cylinder length="0.001" radius="0.005"/>
        </geometry>
      </collision>

    <inertial>
        <mass value="0.5"/>
        <origin xyz="0 0 0" rpy="0 0 0"/>
        <inertia ixx="0.000245" ixy="0" ixz="0" iyy="0.000245" iyz="0" izz="0.000245"/>
    </inertial>

    </link>

  <joint name="back_yaw_joint" type="continuous">
    <origin xyz="-0.14 0.0 -0.0775" rpy="0 0 0"/>
    <parent link="chassis" />
    <child link="back_yaw_link" />
    <axis xyz="0 0 1" />
    <limit effort="1000.0" velocity="100.0" />
    <dynamics damping="0.05" friction="0.1"/>
  </joint>



  <link name="back_roll_link">
      <visual>
        <origin rpy="0 1.5707 1.5707" xyz="0 0 0"/>
        <geometry>
          <cylinder length="0.001" radius="0.005"/>
        </geometry>
        <material name="red"/>
      </visual>

      <collision>
        <origin rpy="0 1.5707 1.5707" xyz="0 0 0"/>
        <geometry>
          <cylinder length="0.001" radius="0.005"/>
        </geometry>
      </collision>

      <inertial>
        <mass value="0.5"/>
        <origin xyz="0 0 0" rpy="0 0 0"/>
        <inertia ixx="0.000245" ixy="0" ixz="0" iyy="0.000245" iyz="0" izz="0.000245"/>
    </inertial>

  </link>

  <joint name="back_roll_joint" type="continuous">
    <origin rpy="0 0 0" xyz="0 0 0" />
    <parent link="back_yaw_link" />
    <child link="back_roll_link" />
    <axis xyz="1 0 0" />
    <limit effort="1000.0" velocity="100.0" />
    <dynamics damping="0.0" friction="0.1"/>
  </joint>


  <link name="back_pitch_link">
    <visual>
      <origin rpy="0 1.5707 1.5707" xyz="0 0 0"/>
      <geometry>
        <sphere radius="0.035"/>
      </geometry>
      <material name="green"/>
    </visual>

    <collision>
      <origin rpy="0 1.5707 1.5707" xyz="0 0 0"/>
      <geometry>
        <sphere radius="0.035"/>
      </geometry>
      <material name="green"/>
    </collision>

    <inertial>
        <mass value="0.5"/>
        <origin xyz="0 0 0" rpy="0 0 0"/>
        <inertia ixx="0.000245" ixy="0" ixz="0" iyy="0.000245" iyz="0" izz="0.000245"/>
    </inertial>

  </link>

    <gazebo reference="back_pitch_link">
        <material>Gazebo/Green</material>
        <mu1>0.1</mu1>
        <mu2>0.1</mu2>
    </gazebo>


  <joint name="back_pitch_joint" type="continuous">
    <origin rpy="0 0 0" xyz="0 0 0" />
    <parent link="back_roll_link" />
    <child link="back_pitch_link" />
    <axis xyz="0 1 0" />
    <limit effort="1000.0" velocity="100.0" />
    <dynamics damping="0.0" friction="0.1"/>
  </joint>


    <!-- Rods 4 pcs -->

    <xacro:standoff_rod link_name="left_front_rod"/>

    <joint name = "left_front_rod_joint" type ="fixed">
        <origin xyz="0.05 0.14 0.1875" rpy="0 0 0"/>
        <parent link = "chassis" />
        <child link = "left_front_rod" />
    </joint>

    <xacro:standoff_rod link_name="left_back_rod" rod_width="0.04"/>

    <joint name = "left_back_rod_joint" type ="fixed">
        <origin xyz="-0.05 0.14 0.1875" rpy="0 0 0"/>
        <parent link = "chassis" />
        <child link = "left_back_rod" />
    </joint>

    <xacro:standoff_rod link_name="right_front_rod" rod_width="0.045"/>

    <joint name = "right_front_rod_joint" type ="fixed">
        <origin xyz="0.05 -0.14 0.1875" rpy="0 0 0"/>
        <parent link = "chassis" />
        <child link = "right_front_rod" />
    </joint>

    <xacro:standoff_rod link_name="right_back_rod" rod_width="0.01"/>

    <joint name = "right_back_rod_joint" type ="fixed">
        <origin xyz="-0.05 -0.14 0.1875" rpy="0 0 0"/>
        <parent link = "chassis" />
        <child link = "right_back_rod" />
    </joint>


    <!-- Cup holder tray -->
    <xacro:cup_holder link_name="cup_holder_link"/>

    <joint name = "cup_holder_link_joint" type ="fixed">
        <origin xyz="0 0 0.3425" rpy="0 0 0"/>
        <parent link = "chassis" />
        <child link = "cup_holder_link" />
    </joint>


    <!-- PLUGINS -->

    <!-- Joint state publisher -->
    <gazebo>
        <plugin name="barista_joint_state" filename="libgazebo_ros_joint_state_publisher.so">
            <ros>
                <namespace>/${robot_name}</namespace>
                <remapping>~/out:=joint_states</remapping>
            </ros>
            <update_rate>30</update_rate>
            <joint_name>left_wheel_joint</joint_name>
            <joint_name>right_wheel_joint</joint_name>

            <joint_name>front_yaw_joint</joint_name>
            <joint_name>back_yaw_joint</joint_name>
            <joint_name>front_roll_joint</joint_name>
            <joint_name>back_roll_joint</joint_name>
            <joint_name>front_pitch_joint</joint_name>
            <joint_name>back_pitch_joint</joint_name>

        </plugin>
    </gazebo>

    <!-- Diff drive plugin -->
    <gazebo>
        <plugin filename="libgazebo_ros_diff_drive.so" name="differential_drive_controller">

            <!-- wheels -->
            <left_joint>left_wheel_joint</left_joint>
            <right_joint>right_wheel_joint</right_joint>

            <!-- kinematics -->
            <wheel_separation>0.3</wheel_separation>
            <wheel_diameter>0.0704</wheel_diameter>

            <!-- limits -->
            <max_wheel_torque>1.0</max_wheel_torque>
            <max_wheel_acceleration>2.0</max_wheel_acceleration>

            <!-- output -->
            <publish_odom>true</publish_odom>
            <publish_odom_tf>true</publish_odom_tf>
            <publish_wheel_tf>false</publish_wheel_tf>

            <ros>
                <namespace>/${robot_name}</namespace>
                <remapping>/cmd_vel:=cmd_vel</remapping>
            </ros>

            <odometry_frame>${robot_name}/odom</odometry_frame>
            <robot_base_frame>${robot_name}/base_link</robot_base_frame>

        </plugin>
    </gazebo>

    <xacro:if value="${include_laser}">

        <xacro:laser_scan_plugin  robot_name="${robot_name}"/>

    </xacro:if>



</robot>